Workbook

Sheet 01_カード一覧（全61枚）
A1: 通しNo | B1: カードID | C1: セット | D1: テーマ | E1: 対象分類 | F1: 受ける物体 | G1: シチュエーション（問題文用） | H1: 力の名称（主表現） | I1: 補助表現 | J1: 作用点と向き | K1: つりあいの関係 | L1: 作用・反作用の相手 | M1: 画像ファイル名
A2: 1 | B2: S01-01 | C2: セット① | D2: 床の上の物体 | E2: 主役物体 | F2: 物体 | G2: 水平な床の上に物体が静止している。 | H2: 物体が地球から受ける力 | I2: （地球が物体を引く力、重力） | J2: 物体の重心・鉛直下向き | K2: No.2 とつりあう | L2: No.4 (S01-04) | M2: 01_S01-01_床の上の物体_物体が地球から受ける力.png
A3: 2 | B3: S01-02 | C3: セット① | D3: 床の上の物体 | E3: 主役物体 | F3: 物体 | G3: 水平な床の上に物体が静止している。 | H3: 物体が床から受ける力 | I3: （床が物体を押す力、垂直抗力） | J3: 物体の下面・鉛直上向き | K3: No.1 とつりあう | L3: No.3 (S01-03) | M3: 02_S01-02_床の上の物体_物体が床から受ける力.png
A4: 3 | B4: S01-03 | C4: セット① | D4: 床の上の物体 | E4: 支持具・面 | F4: 床 | G4: 水平な床の上に物体が静止している。 | H4: 床が物体から受ける力 | I4: （物体が床を押す力） | J4: 床の表面・鉛直下向き | K4: なし（床にはたらく力） | L4: No.2 (S01-02) | M4: 03_S01-03_床の上の物体_床が物体から受ける力.png
A5: 4 | B5: S01-04 | C5: セット① | D5: 床の上の物体 | E5: 地球 | F5: 地球 | G5: 水平な床の上に物体が静止している。 | H5: 地球が物体から受ける力 | I5: （物体が地球を引く力） | J5: 地球の中心・鉛直上向き | K5: なし（地球にはたらく力） | L5: No.1 (S01-01) | M5: 04_S01-04_床の上の物体_地球が物体から受ける力.png
A6: 5 | B6: S02-01 | C6: セット② | D6: 水平面上の球（ばねと糸） | E6: 主役物体 | F6: 球 | G6: なめらかな水平面上にある球を、左右から糸とばねで水平に引いて静止させている。 | H6: 球が糸から受ける力 | I6: （糸が球を引く力、張力） | J6: 球の右端・水平右向き | K6: No.6 とつりあう | L6: No.8 (S02-04) | M6: 05_S02-01_水平面上の球とばねと糸_球が糸から受ける力.png
A7: 6 | B7: S02-02 | C7: セット② | D7: 水平面上の球（ばねと糸） | E7: 主役物体 | F7: 球 | G7: なめらかな水平面上にある球を、左右から糸とばねで水平に引いて静止させている。 | H7: 球がばねから受ける力 | I7: （ばねが球を引く力、弾性力） | J7: 球の左端・水平左向き | K7: No.5 とつりあう | L7: No.7 (S02-03) | M7: 06_S02-02_水平面上の球とばねと糸_球がばねから受ける力.png
A8: 7 | B8: S02-03 | C8: セット② | D8: 水平面上の球（ばねと糸） | E8: 媒介物 | F8: ばね | G8: なめらかな水平面上にある球を、左右から糸とばねで水平に引いて静止させている。 | H8: ばねが球から受ける力 | I8: （球がばねを引く力） | J8: ばねの右端・水平右向き | K8: No.9 とつりあう（ばねのつりあい） | L8: No.6 (S02-02) | M8: 07_S02-03_水平面上の球とばねと糸_ばねが球から受ける力.png
A9: 8 | B9: S02-04 | C9: セット② | D9: 水平面上の球（ばねと糸） | E9: 媒介物 | F9: 糸 | G9: なめらかな水平面上にある球を、左右から糸とばねで水平に引いて静止させている。 | H9: 糸が球から受ける力 | I9: （球が糸を引く力） | J9: 糸の左端・水平左向き | K9: No.11 とつりあう（糸のつりあい） | L9: No.5 (S02-01) | M9: 08_S02-04_水平面上の球とばねと糸_糸が球から受ける力.png
A10: 9 | B10: S02-05 | C10: セット② | D10: 水平面上の球（ばねと糸） | E10: 媒介物 | F10: ばね | G10: なめらかな水平面上にある球を、左右から糸とばねで水平に引いて静止させている。 | H10: ばねが左の壁から受ける力 | I10: （左の壁がばねを引く力） | J10: ばねの左端・水平左向き | K10: No.7 とつりあう（ばねのつりあい） | L10: No.10 (S02-06) | M10: 09_S02-05_水平面上の球とばねと糸_ばねが左の壁から受ける力.png
A11: 10 | B11: S02-06 | C11: セット② | D11: 水平面上の球（ばねと糸） | E11: 支持具・面 | F11: 壁 | G11: なめらかな水平面上にある球を、左右から糸とばねで水平に引いて静止させている。 | H11: 左の壁がばねから受ける力 | I11: （ばねが左の壁を引く力） | J11: 左の壁の表面・水平右向き | K11: なし（壁にはたらく力） | L11: No.9 (S02-05) | M11: 10_S02-06_水平面上の球とばねと糸_左の壁がばねから受ける力.png
A12: 11 | B12: S02-07 | C12: セット② | D12: 水平面上の球（ばねと糸） | E12: 媒介物 | F12: 糸 | G12: なめらかな水平面上にある球を、左右から糸とばねで水平に引いて静止させている。 | H12: 糸が右の壁から受ける力 | I12: （右の壁が糸を引く力） | J12: 糸の右端・水平右向き | K12: No.8 とつりあう（糸のつりあい） | L12: No.12 (S02-08) | M12: 11_S02-07_水平面上の球とばねと糸_糸が右の壁から受ける力.png
A13: 12 | B13: S02-08 | C13: セット② | D13: 水平面上の球（ばねと糸） | E13: 支持具・面 | F13: 壁 | G13: なめらかな水平面上にある球を、左右から糸とばねで水平に引いて静止させている。 | H13: 右の壁が糸から受ける力 | I13: （糸が右の壁を引く力） | J13: 右の壁の表面・水平左向き | K13: なし（壁にはたらく力） | L13: No.11 (S02-07) | M13: 12_S02-08_水平面上の球とばねと糸_右の壁が糸から受ける力.png
... A62: 61 | B62: S09-06 | C62: セット⑨ | D62: 天井につるしたばねとおもり | E62: 支持具・面 | F62: 天井 | G62: 天井からつるしたばねにおもり（球）をつるして静止させている。 | H62: 天井がばねから受ける力 | I62: （ばねが天井を引く力、反作用） | J62: 天井の下面・鉛直下向き | K62: なし（天井にはたらく力） | L62: No.60 (S09-05) | M62: 61_S09-06_天井からつるしたばねとおもり_天井がばねから受ける力.png

Sheet 02_問題バンク（全282問）
A1: 問題ID | B1: 段階・レベル | C1: 出題カテゴリ | D1: セット | E1: テーマ | F1: 問題文（Question Text） | G1: 選択肢1 (①) | H1: 選択肢2 (②) | I1: 選択肢3 (③) | J1: 選択肢4 (④) | K1: 正解番号 | L1: 制限時間(秒) | M1: 使用画像ファイル名 | N1: GitHub公開画像URL（自動生成） | O1: 解説（Answer explanation）
A2: Simple-01 | B2: Lv.1-A（導入：図→名称） | C2: 力の図示と名称（図→言葉） | D2: セット④ | E2: 壁に押し付けられた物体 | F2: 【セット④：壁に押し付けられた物体】鉛直な壁に物体をあて、人が水平に手で押し付けて静止させている。 図の矢印が表している力はどれか。 | G2: 壁が物体から受ける力（物体が壁を押す力） | H2: 物体が壁から受ける力（壁が物体を押す力） | I2: 物体が人から受ける力（人が物体を押す力） | J2: 人が物体から受ける力（物体が人を押す力） | K2: 1 | L2: 30 | M2: 21_S04-03_壁に押し付けられた物体_壁が物体から受ける力.png | N2: ='04_設定_GitHub画像URL'!$B$2 & M2 | O2: 正解：壁が物体から受ける力（物体が壁を押す力）（作用点と向き：壁の表面・水平右向き）。力を受ける物体（主語）は「壁」である。
A3: Simple-02 | B3: Lv.1-B（発展：名称→図） | C3: 力の図示と名称（言葉→図） | D3: セット⑨ | E3: 天井につるしたばねとおもり | F3: 【セット⑨：天井につるしたばねとおもり】天井からつるしたばねにおもり（球）をつるして静止させている。 このとき、「ばねがおもりから受ける力（おもりがばねを引く力）」を表している図はどれか。 | G3: ① | H3: ② | I3: ③ | J3: ④ | K3: 2 | L3: 30 | M3: P58_S09-03_天井からつるしたばねとおもり_4択パネル.png | N3: ='04_設定_GitHub画像URL'!$B$2 & M3 | O3: 正解：②（ばねがおもりから受ける力（おもりがばねを引く力、弾性力の反作用））。作用点と向きは「ばねの下端・鉛直下向き」である。
A4: Simple-03 | B4: Lv.1-B（発展：名称→図） | C4: 力の図示と名称（言葉→図） | D4: セット⑥ | E4: 積み重ねた2物体（床・A・B） | F4: 【セット⑥：積み重ねた2物体（床・A・B）】水平な床の上に物体Aがあり、その上に小さい物体Bを載せて静止させている。 このとき、「物体Aが物体Bから受ける力（物体Bが物体Aを押す力）」を表している図はどれか。 | G4: ① | H4: ② | I4: ③ | J4: ④ | K4: 1 | L4: 30 | M4: P33_S06-05_床の上に積み重ねた2物体AB_4択パネル.png | N4: ='04_設定_GitHub画像URL'!$B$2 & M4 | O4: 正解：①（物体Aが物体Bから受ける力（物体Bが物体Aを押す力、垂直抗力の反作用））。作用点と向きは「物体Aの上面・鉛直下向き」である。
A5: Simple-04 | B5: Lv.2（力のつりあい：2力） | C5: 力のつりあい（2力） | D5: セット① | E5: 床の上の物体 | F5: 【セット①：床の上の物体】水平な床の上に物体が静止している。 このとき、「物体が地球から受ける力（地球が物体を引く力）」と【力のつりあいの関係】にある力はどれか。 | G5: ① | H5: ② | I5: ③ | J5: ④ | K5: 2 | L5: 45 | M5: P02_S01-02_床の上の物体_4択パネル.png | N5: ='04_設定_GitHub画像URL'!$B$2 & M5 | O5: 正解：②（物体が床から受ける力（床が物体を押す力、垂直抗力））。力のつりあいは同じ1つの物体（物体）にはたらく逆向き・同じ大きさの力どうしの関係である。
A6: Simple-05 | B6: Lv.2（力のつりあい：2力） | C6: 力のつりあい（2力） | D6: セット② | E6: 水平面上の球（ばねと糸） | F6: 【セット②：水平面上の球（ばねと糸）】なめらかな水平面上にある球を、左右から糸とばねで水平に引いて静止させている。 このとき、「ばねが球から受ける力（球がばねを引く力）」と【力のつりあいの関係】にある力はどれか。 | G6: ① | H6: ② | I6: ③ | J6: ④ | K6: 1 | L6: 45 | M6: P09_S02-05_水平面上の球とばねと糸_4択パネル.png | N6: ='04_設定_GitHub画像URL'!$B$2 & M6 | O6: 正解：①（ばねが左の壁から受ける力（左の壁がばねを引く力））。力のつりあいは同じ1つの物体（ばね）にはたらく逆向き・同じ大きさの力どうしの関係である。
A7: Simple-06 | B7: Lv.2（力のつりあい：3力合力・発展） | C7: 力のつりあい（3力合力） | D7: セット⑧ | E7: 床・箱・ばね・人（持ち上がらない） | F7: 【セット⑧：床・箱・ばね・人（持ち上がらない）（3力のつりあい）】水平な床の上に箱があり、上からばねを人が引いているが持ち上がらず静止している。 このとき、「箱がばねから受ける力（ばねが箱を引く力）」と「箱が床から受ける力（床が箱を押す力）」の【合力とつりあいの関係】にある力はどれか。 | G7: ① | H7: ② | I7: ③ | J7: ④ | K7: 1 | L7: 60 | M7: P49_S08-01_床の上の箱をばねで上に引く人_4択パネル.png | N7: ='04_設定_GitHub画像URL'!$B$2 & M7 | O7: 正解：①（箱が地球から受ける力（地球が箱を引く力、重力））。箱には上向きに「ばねから受ける力（弾性力）」と「床から受ける力（垂直抗力）」の2力がはたらき、それらの合力と下向きにつりあうのが「箱が地球から受ける力（重力）」である。
A8: Simple-07 | B8: Lv.3（作用・反作用） | C8: 作用・反作用 | D8: セット③ | E8: つるされた球 | F8: 【セット③：つるされた球】天井から軽い糸で球をつるして静止させている。 このとき、「球が地球から受ける力（地球が球を引く力）」と【作用・反作用の関係】にある力はどれか。 | G8: ① | H8: ② | I8: ③ | J8: ④ | K8: 2 | L8: 45 | M8: P13_S03-01_天井から糸でつるされた球_4択パネル.png | N8: ='04_設定_GitHub画像URL'!$B$2 & M8 | O8: 正解：②（地球が球から受ける力（球が地球を引く力））。作用・反作用は主語と相手が入れ替わる（「球が地球から受ける力」⇔「地球が球から受ける力」）。同じ物体が受ける力（つりあい）と混同しないこと。
A9: Simple-08 | B9: Lv.3（作用・反作用） | C9: 作用・反作用 | D9: セット⑥ | E9: 積み重ねた2物体（床・A・B） | F9: 【セット⑥：積み重ねた2物体（床・A・B）】水平な床の上に物体Aがあり、その上に小さい物体Bを載せて静止させている。 このとき、「物体Bが物体Aから受ける力（物体Aが物体Bを押す力）」と【作用・反作用の関係】にある力はどれか。 | G9: ① | H9: ② | I9: ③ | J9: ④ | K9: 1 | L9: 45 | M9: P33_S06-05_床の上に積み重ねた2物体AB_4択パネル.png | N9: ='04_設定_GitHub画像URL'!$B$2 & M9 | O9: 正解：①（物体Aが物体Bから受ける力（物体Bが物体Aを押す力、垂直抗力の反作用））。作用・反作用は主語と相手が入れ替わる（「物体Bが物体Aから受ける力」⇔「物体Aが物体Bから受ける力」）。同じ物体が受ける力（つりあい）と混同しないこと。
A10: Simple-09 | B10: Lv.4（総合：2力関係判定） | C10: 2力の関係判定 | D10: セット⑥ | E10: 積み重ねた2物体（床・A・B） | F10: 【セット⑥：積み重ねた2物体（床・A・B）】水平な床の上に物体Aがあり、その上に小さい物体Bを載せて静止させている。 図の「力A」と「力B」は、力のつりあいの関係にあるか、作用・反作用の関係にあるか、それともどちらでもないか。 | G10: 力のつりあいの関係 | H10: 作用・反作用の関係 | I10: どちらでもない（3力のうちの2力） | K10: 3 | L10: 45 | M10: R13_S06_床の上に積み重ねた2物体AB_2力関係判定.png | N10: ='04_設定_GitHub画像URL'!$B$2 & M10 | O10: 正解：どちらでもない（3力のうちの2力）。力Aは「物体Aが地球から受ける力」、力Bは「物体Aが床から受ける力」。どちらも物体Aが受ける力だが、物体Aには上から「物体Bから受ける力」もはたらくため3力でつりあう。この2力だけでは大きさが等しくならず、つりあわない。
A11: Simple-10 | B11: Lv.2（力のつりあい：3力合力・発展） | C11: 力のつりあい（3力合力） | D11: セット⑤ | E11: 斜面上の物体（3力） | F11: 【セット⑤：斜面上の物体（3力）（3力のつりあい）】あらい斜面の上に物体を置き、静止させている。 このとき、「物体が地球から受ける力（地球が物体を引く力）」と「物体が斜面から垂直に受ける力（斜面が物体を垂直に押す力）」の【合力とつりあいの関係】にある力はどれか。 | G11: ① | H11: ② | I11: ③ | J11: ④ | K11: 3 | L11: 60 | M11: P27_S05-05_あらい斜面上の物体_4択パネル.png | N11: ='04_設定_GitHub画像URL'!$B$2 & M11 | O11: 正解：③（物体が斜面から平行に受ける力（斜面が物体を平行に引く力、静止摩擦力））。斜面上の物体にはたらく3力はつりあっているため、地球から受ける力（重力）と斜面から垂直に受ける力（垂直抗力）の合力とつりあうのは「物体が斜面から平行に受ける力（静止摩擦力）」である。
A12: Lv1A-01 | B12: Lv.1-A（導入：図→名称） | C12: 力の図示と名称（図→言葉） | D12: セット① | E12: 床の上の物体 | F12: 【セット①：床の上の物体】水平な床の上に物体が静止している。 図の矢印が表している力はどれか。 | G12: 物体が地球から受ける力（地球が物体を引く力） | H12: 地球が物体から受ける力（物体が地球を引く力） | I12: 物体が床から受ける力（床が物体を押す力） | J12: 床が物体から受ける力（物体が床を押す力） | K12: 1 | L12: 30 | M12: 01_S01-01_床の上の物体_物体が地球から受ける力.png | N12: ='04_設定_GitHub画像URL'!$B$2 & M12 | O12: 正解：物体が地球から受ける力（地球が物体を引く力、重力）（作用点と向き：物体の重心・鉛直下向き）。力を受ける物体（主語）は「物体」である。
A13: Lv1A-02 | B13: Lv.1-A（導入：図→名称） | C13: 力の図示と名称（図→言葉） | D13: セット① | E13: 床の上の物体 | F13: 【セット①：床の上の物体】水平な床の上に物体が静止している。 図の矢印が表している力はどれか。 | G13: 床が物体から受ける力（物体が床を押す力） | H13: 物体が床から受ける力（床が物体を押す力） | I13: 物体が地球から受ける力（地球が物体を引く力） | J13: 地球が物体から受ける力（物体が地球を引く力） | K13: 2 | L13: 30 | M13: 02_S01-02_床の上の物体_物体が床から受ける力.png | N13: ='04_設定_GitHub画像URL'!$B$2 & M13 | O13: 正解：物体が床から受ける力（床が物体を押す力、垂直抗力）（作用点と向き：物体の下面・鉛直上向き）。力を受ける物体（主語）は「物体」である。
A14: Lv1A-03 | B14: Lv.1-A（導入：図→名称） | C14: 力の図示と名称（図→言葉） | D14: セット① | E14: 床の上の物体 | F14: 【セット①：床の上の物体】水平な床の上に物体が静止している。 図の矢印が表している力はどれか。 | G14: 物体が床から受ける力（床が物体を押す力） | H14: 物体が地球から受ける力（地球が物体を引く力） | I14: 床が物体から受ける力（物体が床を押す力） | J14: 地球が物体から受ける力（物体が地球を引く力） | K14: 3 | L14: 30 | M14: 03_S01-03_床の上の物体_床が物体から受ける力.png | N14: ='04_設定_GitHub画像URL'!$B$2 & M14 | O14: 正解：床が物体から受ける力（物体が床を押す力）（作用点と向き：床の表面・鉛直下向き）。力を受ける物体（主語）は「床」である。
A15: Lv1A-04 | B15: Lv.1-A（導入：図→名称） | C15: 力の図示と名称（図→言葉） | D15: セット① | E15: 床の上の物体 | F15: 【セット①：床の上の物体】水平な床の上に物体が静止している。 図の矢印が表している力はどれか。 | G15: 物体が地球から受ける力（地球が物体を引く力） | H15: 物体が床から受ける力（床が物体を押す力） | I15: 床が物体から受ける力（物体が床を押す力） | J15: 地球が物体から受ける力（物体が地球を引く力） | K15: 4 | L15: 30 | M15: 04_S01-04_床の上の物体_地球が物体から受ける力.png | N15: ='04_設定_GitHub画像URL'!$B$2 & M15 | O15: 正解：地球が物体から受ける力（物体が地球を引く力）（作用点と向き：地球の中心・鉛直上向き）。力を受ける物体（主語）は「地球」である。
A16: Lv1A-05 | B16: Lv.1-A（導入：図→名称） | C16: 力の図示と名称（図→言葉） | D16: セット② | E16: 水平面上の球（ばねと糸） | F16: 【セット②：水平面上の球（ばねと糸）】なめらかな水平面上にある球を、左右から糸とばねで水平に引いて静止させている。 図の矢印が表している力はどれか。 | G16: 球が糸から受ける力（糸が球を引く力） | H16: 糸が球から受ける力（球が糸を引く力） | I16: 球がばねから受ける力（ばねが球を引く力） | J16: 糸が右の壁から受ける力（右の壁が糸を引く力） | K16: 1 | L16: 30 | M16: 05_S02-01_水平面上の球とばねと糸_球が糸から受ける力.png | N16: ='04_設定_GitHub画像URL'!$B$2 & M16 | O16: 正解：球が糸から受ける力（糸が球を引く力、張力）（作用点と向き：球の右端・水平右向き）。力を受ける物体（主語）は「球」である。
A17: Lv1A-06 | B17: Lv.1-A（導入：図→名称） | C17: 力の図示と名称（図→言葉） | D17: セット② | E17: 水平面上の球（ばねと糸） | F17: 【セット②：水平面上の球（ばねと糸）】なめらかな水平面上にある球を、左右から糸とばねで水平に引いて静止させている。 図の矢印が表している力はどれか。 | G17: ばねが球から受ける力（球がばねを引く力） | H17: 球がばねから受ける力（ばねが球を引く力） | I17: 球が糸から受ける力（糸が球を引く力） | J17: ばねが左の壁から受ける力（左の壁がばねを引く力） | K17: 2 | L17: 30 | M17: 06_S02-02_水平面上の球とばねと糸_球がばねから受ける力.png | N17: ='04_設定_GitHub画像URL'!$B$2 & M17 | O17: 正解：球がばねから受ける力（ばねが球を引く力、弾性力）（作用点と向き：球の左端・水平左向き）。力を受ける物体（主語）は「球」である。
A18: Lv1A-07 | B18: Lv.1-A（導入：図→名称） | C18: 力の図示と名称（図→言葉） | D18: セット② | E18: 水平面上の球（ばねと糸） | F18: 【セット②：水平面上の球（ばねと糸）】なめらかな水平面上にある球を、左右から糸とばねで水平に引いて静止させている。 図の矢印が表している力はどれか。 | G18: 球がばねから受ける力（ばねが球を引く力） | H18: ばねが左の壁から受ける力（左の壁がばねを引く力） | I18: ばねが球から受ける力（球がばねを引く力） | J18: 球が糸から受ける力（糸が球を引く力） | K18: 3 | L18: 30 | M18: 07_S02-03_水平面上の球とばねと糸_ばねが球から受ける力.png | N18: ='04_設定_GitHub画像URL'!$B$2 & M18 | O18: 正解：ばねが球から受ける力（球がばねを引く力）（作用点と向き：ばねの右端・水平右向き）。力を受ける物体（主語）は「ばね」である。
A19: Lv1A-08 | B19: Lv.1-A（導入：図→名称） | C19: 力の図示と名称（図→言葉） | D19: セット② | E19: 水平面上の球（ばねと糸） | F19: 【セット②：水平面上の球（ばねと糸）】なめらかな水平面上にある球を、左右から糸とばねで水平に引いて静止させている。 図の矢印が表している力はどれか。 | G19: 球が糸から受ける力（糸が球を引く力） | H19: 糸が右の壁から受ける力（右の壁が糸を引く力） | I19: 球がばねから受ける力（ばねが球を引く力） | J19: 糸が球から受ける力（球が糸を引く力） | K19: 4 | L19: 30 | M19: 08_S02-04_水平面上の球とばねと糸_糸が球から受ける力.png | N19: ='04_設定_GitHub画像URL'!$B$2 & M19 | O19: 正解：糸が球から受ける力（球が糸を引く力）（作用点と向き：糸の左端・水平左向き）。力を受ける物体（主語）は「糸」である。
A20: Lv1A-09 | B20: Lv.1-A（導入：図→名称） | C20: 力の図示と名称（図→言葉） | D20: セット② | E20: 水平面上の球（ばねと糸） | F20: 【セット②：水平面上の球（ばねと糸）】なめらかな水平面上にある球を、左右から糸とばねで水平に引いて静止させている。 図の矢印が表している力はどれか。 | G20: ばねが左の壁から受ける力（左の壁がばねを引く力） | H20: 左の壁がばねから受ける力（ばねが左の壁を引く力） | I20: ばねが球から受ける力（球がばねを引く力） | J20: 球が糸から受ける力（糸が球を引く力） | K20: 1 | L20: 30 | M20: 09_S02-05_水平面上の球とばねと糸_ばねが左の壁から受ける力.png | N20: ='04_設定_GitHub画像URL'!$B$2 & M20 | O20: 正解：ばねが左の壁から受ける力（左の壁がばねを引く力）（作用点と向き：ばねの左端・水平左向き）。力を受ける物体（主語）は「ばね」である。
A21: Lv1A-10 | B21: Lv.1-A（導入：図→名称） | C21: 力の図示と名称（図→言葉） | D21: セット② | E21: 水平面上の球（ばねと糸） | F21: 【セット②：水平面上の球（ばねと糸）】なめらかな水平面上にある球を、左右から糸とばねで水平に引いて静止させている。 図の矢印が表している力はどれか。 | G21: ばねが左の壁から受ける力（左の壁がばねを引く力） | H21: 左の壁がばねから受ける力（ばねが左の壁を引く力） | I21: ばねが球から受ける力（球がばねを引く力） | J21: 球が糸から受ける力（糸が球を引く力） | K21: 2 | L21: 30 | M21: 10_S02-06_水平面上の球とばねと糸_左の壁がばねから受ける力.png | N21: ='04_設定_GitHub画像URL'!$B$2 & M21 | O21: 正解：左の壁がばねから受ける力（ばねが左の壁を引く力）（作用点と向き：左の壁の表面・水平右向き）。力を受ける物体（主語）は「壁」である。
A22: Lv1A-11 | B22: Lv.1-A（導入：図→名称） | C22: 力の図示と名称（図→言葉） | D22: セット② | E22: 水平面上の球（ばねと糸） | F22: 【セット②：水平面上の球（ばねと糸）】なめらかな水平面上にある球を、左右から糸とばねで水平に引いて静止させている。 図の矢印が表している力はどれか。 | G22: 右の壁が糸から受ける力（糸が右の壁を引く力） | H22: 糸が球から受ける力（球が糸を引く力） | I22: 糸が右の壁から受ける力（右の壁が糸を引く力） | J22: 球が糸から受ける力（糸が球を引く力） | K22: 3 | L22: 30 | M22: 11_S02-07_水平面上の球とばねと糸_糸が右の壁から受ける力.png | N22: ='04_設定_GitHub画像URL'!$B$2 & M22 | O22: 正解：糸が右の壁から受ける力（右の壁が糸を引く力）（作用点と向き：糸の右端・水平右向き）。力を受ける物体（主語）は「糸」である。
... A233: Lv3-60 | B233: Lv.3（作用・反作用） | C233: 作用・反作用 | D233: セット⑨ | E233: 天井につるしたばねとおもり | F233: 【セット⑨：天井につるしたばねとおもり】天井からつるしたばねにおもり（球）をつるして静止させている。 このとき、「天井がばねから受ける力（ばねが天井を引く力）」と【作用・反作用の関係】にある力はどれか。 | G233: ① | H233: ② | I233: ③ | J233: ④ | K233: 2 | L233: 45 | M233: P61_S09-06_天井からつるしたばねとおもり_4択パネル.png | N233: ='04_設定_GitHub画像URL'!$B$2 & M233 | O233: 正解：②（ばねが天井から受ける力（天井がばねを引く力））。作用・反作用は主語と相手が入れ替わる（「天井がばねから受ける力」⇔「ばねが天井から受ける力」）。同じ物体が受ける力（つりあい）と混同しないこと。
A234: Lv4-01 | B234: Lv.4（総合：2力関係判定） | C234: 2力の関係判定 | D234: セット① | E234: 床の上の物体 | F234: 【セット①：床の上の物体】水平な床の上に物体が静止している。 図の「力A」と「力B」は、力のつりあいの関係にあるか、作用・反作用の関係にあるか、それともどちらでもないか。 | G234: 力のつりあいの関係 | H234: 作用・反作用の関係 | I234: どちらでもない（3力のうちの2力） | K234: 1 | L234: 45 | M234: R01_S01_床の上の物体_2力関係判定.png | N234: ='04_設定_GitHub画像URL'!$B$2 & M234 | O234: 正解：力のつりあいの関係。力Aは「物体が地球から受ける力」、力Bは「物体が床から受ける力」。どちらも同じ「物体」が受ける力（下向きの重力と上向きの垂直抗力）であり、力のつりあいの関係にある。
A235: Lv4-02 | B235: Lv.4（総合：2力関係判定） | C235: 2力の関係判定 | D235: セット① | E235: 床の上の物体 | F235: 【セット①：床の上の物体】水平な床の上に物体が静止している。 図の「力A」と「力B」は、力のつりあいの関係にあるか、作用・反作用の関係にあるか、それともどちらでもないか。 | G235: 力のつりあいの関係 | H235: 作用・反作用の関係 | I235: どちらでもない（3力のうちの2力） | K235: 2 | L235: 45 | M235: R02_S01_床の上の物体_2力関係判定.png | N235: ='04_設定_GitHub画像URL'!$B$2 & M235 | O235: 正解：作用・反作用の関係。力Aは「物体が床から受ける力」、力Bは「床が物体から受ける力」。「物体が床から受ける力」と「床が物体から受ける力」で主語と相手が入れ替わっており、作用・反作用の関係にある。
A236: Lv4-03 | B236: Lv.4（総合：2力関係判定） | C236: 2力の関係判定 | D236: セット② | E236: 水平面上の球（ばねと糸） | F236: 【セット②：水平面上の球（ばねと糸）】なめらかな水平面上にある球を、左右から糸とばねで水平に引いて静止させている。 図の「力A」と「力B」は、力のつりあいの関係にあるか、作用・反作用の関係にあるか、それともどちらでもないか。 | G236: 力のつりあいの関係 | H236: 作用・反作用の関係 | I236: どちらでもない（3力のうちの2力） | K236: 1 | L236: 45 | M236: R03_S02_水平面上の球とばねと糸_2力関係判定.png | N236: ='04_設定_GitHub画像URL'!$B$2 & M236 | O236: 正解：力のつりあいの関係。力Aは「球が糸から受ける力」、力Bは「球がばねから受ける力」。どちらも同じ「球」が左右から受ける力であり、力のつりあいの関係にある。
A237: Lv4-04 | B237: Lv.4（総合：2力関係判定） | C237: 2力の関係判定 | D237: セット② | E237: 水平面上の球（ばねと糸） | F237: 【セット②：水平面上の球（ばねと糸）】なめらかな水平面上にある球を、左右から糸とばねで水平に引いて静止させている。 図の「力A」と「力B」は、力のつりあいの関係にあるか、作用・反作用の関係にあるか、それともどちらでもないか。 | G237: 力のつりあいの関係 | H237: 作用・反作用の関係 | I237: どちらでもない（3力のうちの2力） | K237: 2 | L237: 45 | M237: R04_S02_水平面上の球とばねと糸_2力関係判定.png | N237: ='04_設定_GitHub画像URL'!$B$2 & M237 | O237: 正解：作用・反作用の関係。力Aは「球がばねから受ける力」、力Bは「ばねが球から受ける力」。「球がばねから受ける力」と「ばねが球から受ける力」で主語と相手が入れ替わっており、作用・反作用の関係にある。
A238: Lv4-05 | B238: Lv.4（総合：2力関係判定） | C238: 2力の関係判定 | D238: セット③ | E238: つるされた球 | F238: 【セット③：つるされた球】天井から軽い糸で球をつるして静止させている。 図の「力A」と「力B」は、力のつりあいの関係にあるか、作用・反作用の関係にあるか、それともどちらでもないか。 | G238: 力のつりあいの関係 | H238: 作用・反作用の関係 | I238: どちらでもない（3力のうちの2力） | K238: 1 | L238: 45 | M238: R05_S03_天井から糸でつるされた球_2力関係判定.png | N238: ='04_設定_GitHub画像URL'!$B$2 & M238 | O238: 正解：力のつりあいの関係。力Aは「球が地球から受ける力」、力Bは「球が糸から受ける力」。どちらも同じ「球」が受ける力（下向きの重力と上向きの張力）であり、力のつりあいの関係にある。
A239: Lv4-06 | B239: Lv.4（総合：2力関係判定） | C239: 2力の関係判定 | D239: セット③ | E239: つるされた球 | F239: 【セット③：つるされた球】天井から軽い糸で球をつるして静止させている。 図の「力A」と「力B」は、力のつりあいの関係にあるか、作用・反作用の関係にあるか、それともどちらでもないか。 | G239: 力のつりあいの関係 | H239: 作用・反作用の関係 | I239: どちらでもない（3力のうちの2力） | K239: 2 | L239: 45 | M239: R06_S03_天井から糸でつるされた球_2力関係判定.png | N239: ='04_設定_GitHub画像URL'!$B$2 & M239 | O239: 正解：作用・反作用の関係。力Aは「球が糸から受ける力」、力Bは「糸が球から受ける力」。「球が糸から受ける力」と「糸が球から受ける力」で主語と相手が入れ替わっており、作用・反作用の関係にある。
A240: Lv4-07 | B240: Lv.4（総合：2力関係判定） | C240: 2力の関係判定 | D240: セット④ | E240: 壁に押し付けられた物体 | F240: 【セット④：壁に押し付けられた物体】鉛直な壁に物体をあて、人が水平に手で押し付けて静止させている。 図の「力A」と「力B」は、力のつりあいの関係にあるか、作用・反作用の関係にあるか、それともどちらでもないか。 | G240: 力のつりあいの関係 | H240: 作用・反作用の関係 | I240: どちらでもない（3力のうちの2力） | K240: 1 | L240: 45 | M240: R07_S04_壁に押し付けられた物体_2力関係判定.png | N240: ='04_設定_GitHub画像URL'!$B$2 & M240 | O240: 正解：力のつりあいの関係。力Aは「物体が人から受ける力」、力Bは「物体が壁から受ける力」。どちらも同じ「物体」が水平方向に人・壁から受ける力であり、力のつりあいの関係にある。
A241: Lv4-08 | B241: Lv.4（総合：2力関係判定） | C241: 2力の関係判定 | D241: セット④ | E241: 壁に押し付けられた物体 | F241: 【セット④：壁に押し付けられた物体】鉛直な壁に物体をあて、人が水平に手で押し付けて静止させている。 図の「力A」と「力B」は、力のつりあいの関係にあるか、作用・反作用の関係にあるか、それともどちらでもないか。 | G241: 力のつりあいの関係 | H241: 作用・反作用の関係 | I241: どちらでもない（3力のうちの2力） | K241: 2 | L241: 45 | M241: R08_S04_壁に押し付けられた物体_2力関係判定.png | N241: ='04_設定_GitHub画像URL'!$B$2 & M241 | O241: 正解：作用・反作用の関係。力Aは「物体が壁から受ける力」、力Bは「壁が物体から受ける力」。「物体が壁から受ける力」と「壁が物体から受ける力」で主語と相手が入れ替わっており、作用・反作用の関係にある。
A242: Lv4-09 | B242: Lv.4（総合：2力関係判定） | C242: 2力の関係判定 | D242: セット⑤ | E242: 斜面上の物体（3力） | F242: 【セット⑤：斜面上の物体（3力）】あらい斜面の上に物体を置き、静止させている。 図の「力A」と「力B」は、力のつりあいの関係にあるか、作用・反作用の関係にあるか、それともどちらでもないか。 | G242: 力のつりあいの関係 | H242: 作用・反作用の関係 | I242: どちらでもない（3力のうちの2力） | K242: 2 | L242: 45 | M242: R09_S05_あらい斜面上の物体_2力関係判定.png | N242: ='04_設定_GitHub画像URL'!$B$2 & M242 | O242: 正解：作用・反作用の関係。力Aは「物体が斜面から垂直に受ける力」、力Bは「斜面が物体から垂直に受ける力」。「物体が斜面から垂直に受ける力」と「斜面が物体から垂直に受ける力」で主語と相手が入れ替わっており、作用・反作用の関係にある。
A243: Lv4-10 | B243: Lv.4（総合：2力関係判定） | C243: 2力の関係判定 | D243: セット⑤ | E243: 斜面上の物体（3力） | F243: 【セット⑤：斜面上の物体（3力）】あらい斜面の上に物体を置き、静止させている。 図の「力A」と「力B」は、力のつりあいの関係にあるか、作用・反作用の関係にあるか、それともどちらでもないか。 | G243: 力のつりあいの関係 | H243: 作用・反作用の関係 | I243: どちらでもない（3力のうちの2力） | K243: 3 | L243: 45 | M243: R10_S05_あらい斜面上の物体_2力関係判定.png | N243: ='04_設定_GitHub画像URL'!$B$2 & M243 | O243: 正解：どちらでもない（3力のうちの2力）。力Aは「物体が地球から受ける力」、力Bは「物体が斜面から垂直に受ける力」。同じ物体にはたらく力だが、斜面上の物体は「斜面から平行に受ける力（静止摩擦力）」も合わせた3力でつりあうため、この2力だけではつりあわない。
A244: Lv4-11 | B244: Lv.4（総合：2力関係判定） | C244: 2力の関係判定 | D244: セット⑥ | E244: 積み重ねた2物体（床・A・B） | F244: 【セット⑥：積み重ねた2物体（床・A・B）】水平な床の上に物体Aがあり、その上に小さい物体Bを載せて静止させている。 図の「力A」と「力B」は、力のつりあいの関係にあるか、作用・反作用の関係にあるか、それともどちらでもないか。 | G244: 力のつりあいの関係 | H244: 作用・反作用の関係 | I244: どちらでもない（3力のうちの2力） | K244: 1 | L244: 45 | M244: R11_S06_床の上に積み重ねた2物体AB_2力関係判定.png | N244: ='04_設定_GitHub画像URL'!$B$2 & M244 | O244: 正解：力のつりあいの関係。力Aは「物体Bが地球から受ける力」、力Bは「物体Bが物体Aから受ける力」。どちらも上の「物体B」が受ける2力（重力とAからの垂直抗力）であり、力のつりあいの関係にある。
A245: Lv4-12 | B245: Lv.4（総合：2力関係判定） | C245: 2力の関係判定 | D245: セット⑥ | E245: 積み重ねた2物体（床・A・B） | F245: 【セット⑥：積み重ねた2物体（床・A・B）】水平な床の上に物体Aがあり、その上に小さい物体Bを載せて静止させている。 図の「力A」と「力B」は、力のつりあいの関係にあるか、作用・反作用の関係にあるか、それともどちらでもないか。 | G245: 力のつりあいの関係 | H245: 作用・反作用の関係 | I245: どちらでもない（3力のうちの2力） | K245: 2 | L245: 45 | M245: R12_S06_床の上に積み重ねた2物体AB_2力関係判定.png | N245: ='04_設定_GitHub画像URL'!$B$2 & M245 | O245: 正解：作用・反作用の関係。力Aは「物体Bが物体Aから受ける力」、力Bは「物体Aが物体Bから受ける力」。「物体Bが物体Aから受ける力」と「物体Aが物体Bから受ける力」で主語と相手が入れ替わっており、作用・反作用の関係にある。
... A251: Lv4-18 | B251: Lv.4（総合：2力関係判定） | C251: 2力の関係判定 | D251: セット⑨ | E251: 天井につるしたばねとおもり | F251: 【セット⑨：天井につるしたばねとおもり】天井からつるしたばねにおもり（球）をつるして静止させている。 図の「力A」と「力B」は、力のつりあいの関係にあるか、作用・反作用の関係にあるか、それともどちらでもないか。 | G251: 力のつりあいの関係 | H251: 作用・反作用の関係 | I251: どちらでもない（3力のうちの2力） | K251: 2 | L251: 45 | M251: R18_S09_天井からつるしたばねとおもり_2力関係判定.png | N251: ='04_設定_GitHub画像URL'!$B$2 & M251 | O251: 正解：作用・反作用の関係。力Aは「おもりがばねから受ける力」、力Bは「ばねがおもりから受ける力」。「おもりがばねから受ける力」と「ばねがおもりから受ける力」で主語と相手が入れ替わっており、作用・反作用の関係にある。
A252: Lv4-19 | B252: Lv.4（総合：力はどれか） | C252: 力の図示と名称（言葉→図） | D252: セット① | E252: 床の上の物体 | F252: 【セット①：床の上の物体】水平な床の上に物体が静止している。 このとき、「物体が地球から受ける力（地球が物体を引く力）」を表している図はどれか。 | G252: ① | H252: ② | I252: ③ | J252: ④ | K252: 1 | L252: 30 | M252: P01_S01-01_床の上の物体_4択パネル.png | N252: ='04_設定_GitHub画像URL'!$B$2 & M252 | O252: 正解：①（物体が地球から受ける力（地球が物体を引く力、重力））。作用点と向きは「物体の重心・鉛直下向き」である。
A253: Lv4-20 | B253: Lv.4（総合：力はどれか） | C253: 力の図示と名称（言葉→図） | D253: セット② | E253: 水平面上の球（ばねと糸） | F253: 【セット②：水平面上の球（ばねと糸）】なめらかな水平面上にある球を、左右から糸とばねで水平に引いて静止させている。 このとき、「ばねが球から受ける力（球がばねを引く力）」を表している図はどれか。 | G253: ① | H253: ② | I253: ③ | J253: ④ | K253: 3 | L253: 30 | M253: P07_S02-03_水平面上の球とばねと糸_4択パネル.png | N253: ='04_設定_GitHub画像URL'!$B$2 & M253 | O253: 正解：③（ばねが球から受ける力（球がばねを引く力））。作用点と向きは「ばねの右端・水平右向き」である。
A254: Lv4-21 | B254: Lv.4（総合：力はどれか） | C254: 力の図示と名称（言葉→図） | D254: セット③ | E254: つるされた球 | F254: 【セット③：つるされた球】天井から軽い糸で球をつるして静止させている。 このとき、「糸が球から受ける力（球が糸を引く力）」を表している図はどれか。 | G254: ① | H254: ② | I254: ③ | J254: ④ | K254: 3 | L254: 30 | M254: P15_S03-03_天井から糸でつるされた球_4択パネル.png | N254: ='04_設定_GitHub画像URL'!$B$2 & M254 | O254: 正解：③（糸が球から受ける力（球が糸を引く力））。作用点と向きは「糸の下端・鉛直下向き」である。
A255: Lv4-22 | B255: Lv.4（総合：力はどれか） | C255: 力の図示と名称（言葉→図） | D255: セット④ | E255: 壁に押し付けられた物体 | F255: 【セット④：壁に押し付けられた物体】鉛直な壁に物体をあて、人が水平に手で押し付けて静止させている。 このとき、「壁が物体から受ける力（物体が壁を押す力）」を表している図はどれか。 | G255: ① | H255: ② | I255: ③ | J255: ④ | K255: 1 | L255: 30 | M255: P21_S04-03_壁に押し付けられた物体_4択パネル.png | N255: ='04_設定_GitHub画像URL'!$B$2 & M255 | O255: 正解：①（壁が物体から受ける力（物体が壁を押す力））。作用点と向きは「壁の表面・水平右向き」である。
...

Sheet 03_授業用シンプルクイズ10問
A1: 問題ID | B1: 段階・レベル | C1: 出題カテゴリ | D1: セット | E1: テーマ | F1: 問題文（Question Text） | G1: 選択肢1 (①) | H1: 選択肢2 (②) | I1: 選択肢3 (③) | J1: 選択肢4 (④) | K1: 正解番号 | L1: 制限時間(秒) | M1: 使用画像ファイル名 | N1: GitHub公開画像URL（自動生成） | O1: 解説（Answer explanation）
A2: Simple-01 | B2: Lv.1-A（導入：図→名称） | C2: 力の図示と名称（図→言葉） | D2: セット④ | E2: 壁に押し付けられた物体 | F2: 【セット④：壁に押し付けられた物体】鉛直な壁に物体をあて、人が水平に手で押し付けて静止させている。 図の矢印が表している力はどれか。 | G2: 壁が物体から受ける力（物体が壁を押す力） | H2: 物体が壁から受ける力（壁が物体を押す力） | I2: 物体が人から受ける力（人が物体を押す力） | J2: 人が物体から受ける力（物体が人を押す力） | K2: 1 | L2: 30 | M2: 21_S04-03_壁に押し付けられた物体_壁が物体から受ける力.png | N2: ='04_設定_GitHub画像URL'!$B$2 & M2 | O2: 正解：壁が物体から受ける力（物体が壁を押す力）（作用点と向き：壁の表面・水平右向き）。力を受ける物体（主語）は「壁」である。
A3: Simple-02 | B3: Lv.1-B（発展：名称→図） | C3: 力の図示と名称（言葉→図） | D3: セット⑨ | E3: 天井につるしたばねとおもり | F3: 【セット⑨：天井につるしたばねとおもり】天井からつるしたばねにおもり（球）をつるして静止させている。 このとき、「ばねがおもりから受ける力（おもりがばねを引く力）」を表している図はどれか。 | G3: ① | H3: ② | I3: ③ | J3: ④ | K3: 2 | L3: 30 | M3: P58_S09-03_天井からつるしたばねとおもり_4択パネル.png | N3: ='04_設定_GitHub画像URL'!$B$2 & M3 | O3: 正解：②（ばねがおもりから受ける力（おもりがばねを引く力、弾性力の反作用））。作用点と向きは「ばねの下端・鉛直下向き」である。
A4: Simple-03 | B4: Lv.1-B（発展：名称→図） | C4: 力の図示と名称（言葉→図） | D4: セット⑥ | E4: 積み重ねた2物体（床・A・B） | F4: 【セット⑥：積み重ねた2物体（床・A・B）】水平な床の上に物体Aがあり、その上に小さい物体Bを載せて静止させている。 このとき、「物体Aが物体Bから受ける力（物体Bが物体Aを押す力）」を表している図はどれか。 | G4: ① | H4: ② | I4: ③ | J4: ④ | K4: 1 | L4: 30 | M4: P33_S06-05_床の上に積み重ねた2物体AB_4択パネル.png | N4: ='04_設定_GitHub画像URL'!$B$2 & M4 | O4: 正解：①（物体Aが物体Bから受ける力（物体Bが物体Aを押す力、垂直抗力の反作用））。作用点と向きは「物体Aの上面・鉛直下向き」である。
A5: Simple-04 | B5: Lv.2（力のつりあい：2力） | C5: 力のつりあい（2力） | D5: セット① | E5: 床の上の物体 | F5: 【セット①：床の上の物体】水平な床の上に物体が静止している。 このとき、「物体が地球から受ける力（地球が物体を引く力）」と【力のつりあいの関係】にある力はどれか。 | G5: ① | H5: ② | I5: ③ | J5: ④ | K5: 2 | L5: 45 | M5: P02_S01-02_床の上の物体_4択パネル.png | N5: ='04_設定_GitHub画像URL'!$B$2 & M5 | O5: 正解：②（物体が床から受ける力（床が物体を押す力、垂直抗力））。力のつりあいは同じ1つの物体（物体）にはたらく逆向き・同じ大きさの力どうしの関係である。
A6: Simple-05 | B6: Lv.2（力のつりあい：2力） | C6: 力のつりあい（2力） | D6: セット② | E6: 水平面上の球（ばねと糸） | F6: 【セット②：水平面上の球（ばねと糸）】なめらかな水平面上にある球を、左右から糸とばねで水平に引いて静止させている。 このとき、「ばねが球から受ける力（球がばねを引く力）」と【力のつりあいの関係】にある力はどれか。 | G6: ① | H6: ② | I6: ③ | J6: ④ | K6: 1 | L6: 45 | M6: P09_S02-05_水平面上の球とばねと糸_4択パネル.png | N6: ='04_設定_GitHub画像URL'!$B$2 & M6 | O6: 正解：①（ばねが左の壁から受ける力（左の壁がばねを引く力））。力のつりあいは同じ1つの物体（ばね）にはたらく逆向き・同じ大きさの力どうしの関係である。
A7: Simple-06 | B7: Lv.2（力のつりあい：3力合力・発展） | C7: 力のつりあい（3力合力） | D7: セット⑧ | E7: 床・箱・ばね・人（持ち上がらない） | F7: 【セット⑧：床・箱・ばね・人（持ち上がらない）（3力のつりあい）】水平な床の上に箱があり、上からばねを人が引いているが持ち上がらず静止している。 このとき、「箱がばねから受ける力（ばねが箱を引く力）」と「箱が床から受ける力（床が箱を押す力）」の【合力とつりあいの関係】にある力はどれか。 | G7: ① | H7: ② | I7: ③ | J7: ④ | K7: 1 | L7: 60 | M7: P49_S08-01_床の上の箱をばねで上に引く人_4択パネル.png | N7: ='04_設定_GitHub画像URL'!$B$2 & M7 | O7: 正解：①（箱が地球から受ける力（地球が箱を引く力、重力））。箱には上向きに「ばねから受ける力（弾性力）」と「床から受ける力（垂直抗力）」の2力がはたらき、それらの合力と下向きにつりあうのが「箱が地球から受ける力（重力）」である。
A8: Simple-07 | B8: Lv.3（作用・反作用） | C8: 作用・反作用 | D8: セット③ | E8: つるされた球 | F8: 【セット③：つるされた球】天井から軽い糸で球をつるして静止させている。 このとき、「球が地球から受ける力（地球が球を引く力）」と【作用・反作用の関係】にある力はどれか。 | G8: ① | H8: ② | I8: ③ | J8: ④ | K8: 2 | L8: 45 | M8: P13_S03-01_天井から糸でつるされた球_4択パネル.png | N8: ='04_設定_GitHub画像URL'!$B$2 & M8 | O8: 正解：②（地球が球から受ける力（球が地球を引く力））。作用・反作用は主語と相手が入れ替わる（「球が地球から受ける力」⇔「地球が球から受ける力」）。同じ物体が受ける力（つりあい）と混同しないこと。
A9: Simple-08 | B9: Lv.3（作用・反作用） | C9: 作用・反作用 | D9: セット⑥ | E9: 積み重ねた2物体（床・A・B） | F9: 【セット⑥：積み重ねた2物体（床・A・B）】水平な床の上に物体Aがあり、その上に小さい物体Bを載せて静止させている。 このとき、「物体Bが物体Aから受ける力（物体Aが物体Bを押す力）」と【作用・反作用の関係】にある力はどれか。 | G9: ① | H9: ② | I9: ③ | J9: ④ | K9: 1 | L9: 45 | M9: P33_S06-05_床の上に積み重ねた2物体AB_4択パネル.png | N9: ='04_設定_GitHub画像URL'!$B$2 & M9 | O9: 正解：①（物体Aが物体Bから受ける力（物体Bが物体Aを押す力、垂直抗力の反作用））。作用・反作用は主語と相手が入れ替わる（「物体Bが物体Aから受ける力」⇔「物体Aが物体Bから受ける力」）。同じ物体が受ける力（つりあい）と混同しないこと。
A10: Simple-09 | B10: Lv.4（総合：2力関係判定） | C10: 2力の関係判定 | D10: セット⑥ | E10: 積み重ねた2物体（床・A・B） | F10: 【セット⑥：積み重ねた2物体（床・A・B）】水平な床の上に物体Aがあり、その上に小さい物体Bを載せて静止させている。 図の「力A」と「力B」は、力のつりあいの関係にあるか、作用・反作用の関係にあるか、それともどちらでもないか。 | G10: 力のつりあいの関係 | H10: 作用・反作用の関係 | I10: どちらでもない（3力のうちの2力） | K10: 3 | L10: 45 | M10: R13_S06_床の上に積み重ねた2物体AB_2力関係判定.png | N10: ='04_設定_GitHub画像URL'!$B$2 & M10 | O10: 正解：どちらでもない（3力のうちの2力）。力Aは「物体Aが地球から受ける力」、力Bは「物体Aが床から受ける力」。どちらも物体Aが受ける力だが、物体Aには上から「物体Bから受ける力」もはたらくため3力でつりあう。この2力だけでは大きさが等しくならず、つりあわない。
A11: Simple-10 | B11: Lv.2（力のつりあい：3力合力・発展） | C11: 力のつりあい（3力合力） | D11: セット⑤ | E11: 斜面上の物体（3力） | F11: 【セット⑤：斜面上の物体（3力）（3力のつりあい）】あらい斜面の上に物体を置き、静止させている。 このとき、「物体が地球から受ける力（地球が物体を引く力）」と「物体が斜面から垂直に受ける力（斜面が物体を垂直に押す力）」の【合力とつりあいの関係】にある力はどれか。 | G11: ① | H11: ② | I11: ③ | J11: ④ | K11: 3 | L11: 60 | M11: P27_S05-05_あらい斜面上の物体_4択パネル.png | N11: ='04_設定_GitHub画像URL'!$B$2 & M11 | O11: 正解：③（物体が斜面から平行に受ける力（斜面が物体を平行に引く力、静止摩擦力））。斜面上の物体にはたらく3力はつりあっているため、地球から受ける力（重力）と斜面から垂直に受ける力（垂直抗力）の合力とつりあうのは「物体が斜面から平行に受ける力（静止摩擦力）」である。

Sheet 04_設定_GitHub画像URL
A1: 設定項目 | B1: 設定値（GitHubリポジトリ作成後にB2セルを書き換えるか、update_github_urls.pyを実行してください）
A2: GitHub Raw画像ベースURL | B2: https://raw.githubusercontent.com/phys-ken/physics-force-cards/main/
A3: 説明 | B3: 末尾には必ずスラッシュ( / )を入れてください。例: https://raw.githubusercontent.com/phys-ken/physics-force-cards/main/
